2021-12-07 13:54:26,323 ERROR: Exception on /favicon.ico [GET] [in C:\Users\Миша\PycharmProjects\VIT 2.0\venv\lib\site-packages\flask\app.py:1457]
Traceback (most recent call last):
  File "C:\Users\Миша\PycharmProjects\VIT 2.0\venv\lib\site-packages\flask\app.py", line 1516, in full_dispatch_request
    rv = self.dispatch_request()
  File "C:\Users\Миша\PycharmProjects\VIT 2.0\venv\lib\site-packages\flask\app.py", line 1492, in dispatch_request
    self.raise_routing_exception(req)
  File "C:\Users\Миша\PycharmProjects\VIT 2.0\venv\lib\site-packages\flask\app.py", line 1474, in raise_routing_exception
    raise request.routing_exception  # type: ignore
  File "C:\Users\Миша\PycharmProjects\VIT 2.0\venv\lib\site-packages\flask\ctx.py", line 367, in match_request
    result = self.url_adapter.match(return_rule=True)  # type: ignore
  File "C:\Users\Миша\PycharmProjects\VIT 2.0\venv\lib\site-packages\werkzeug\routing.py", line 2041, in match
    raise NotFound()
werkzeug.exceptions.NotFound: 404 Not Found: The requested URL was not found on the server. If you entered the URL manually please check your spelling and try again.

During handling of the above exception, another exception occurred:

Traceback (most recent call last):
  File "C:\Users\Миша\PycharmProjects\VIT 2.0\venv\lib\site-packages\flask\app.py", line 2073, in wsgi_app
    response = self.full_dispatch_request()
  File "C:\Users\Миша\PycharmProjects\VIT 2.0\venv\lib\site-packages\flask\app.py", line 1518, in full_dispatch_request
    rv = self.handle_user_exception(e)
  File "C:\Users\Миша\PycharmProjects\VIT 2.0\venv\lib\site-packages\flask\app.py", line 1386, in handle_user_exception
    return self.handle_http_exception(e)
  File "C:\Users\Миша\PycharmProjects\VIT 2.0\venv\lib\site-packages\flask\app.py", line 1326, in handle_http_exception
    return self.ensure_sync(handler)(e)
  File "C:\Users\Миша\PycharmProjects\VIT 2.0\app\errors.py", line 7, in not_found_error
    return render_template('404.html'), 404
  File "C:\Users\Миша\PycharmProjects\VIT 2.0\venv\lib\site-packages\flask\templating.py", line 147, in render_template
    return _render(
  File "C:\Users\Миша\PycharmProjects\VIT 2.0\venv\lib\site-packages\flask\templating.py", line 128, in _render
    rv = template.render(context)
  File "C:\Users\Миша\PycharmProjects\VIT 2.0\venv\lib\site-packages\jinja2\environment.py", line 1291, in render
    self.environment.handle_exception()
  File "C:\Users\Миша\PycharmProjects\VIT 2.0\venv\lib\site-packages\jinja2\environment.py", line 925, in handle_exception
    raise rewrite_traceback_stack(source=source)
  File "C:\Users\Миша\PycharmProjects\VIT 2.0\app\templates\404.html", line 1, in top-level template code
    {% extends "base.html" %}
  File "C:\Users\Миша\PycharmProjects\VIT 2.0\app\templates\base.html", line 1, in top-level template code
    {% extends 'bootstrap/base.html' %}
  File "C:\Users\Миша\PycharmProjects\VIT 2.0\venv\lib\site-packages\flask_bootstrap\templates\bootstrap\base.html", line 1, in top-level template code
    {% block doc -%}
  File "C:\Users\Миша\PycharmProjects\VIT 2.0\venv\lib\site-packages\flask_bootstrap\templates\bootstrap\base.html", line 4, in block 'doc'
    {%- block html %}
  File "C:\Users\Миша\PycharmProjects\VIT 2.0\venv\lib\site-packages\flask_bootstrap\templates\bootstrap\base.html", line 20, in block 'html'
    {% block body -%}
  File "C:\Users\Миша\PycharmProjects\VIT 2.0\venv\lib\site-packages\flask_bootstrap\templates\bootstrap\base.html", line 26, in block 'body'
    {% block scripts %}
  File "C:\Users\Миша\PycharmProjects\VIT 2.0\app\templates\base.html", line 54, in block 'scripts'
    {{ moment.include() }}
  File "C:\Users\Миша\PycharmProjects\VIT 2.0\venv\lib\site-packages\jinja2\utils.py", line 84, in from_obj
    if hasattr(obj, "jinja_pass_arg"):
jinja2.exceptions.UndefinedError: 'type object' has no attribute 'include'
