2021-12-07 13:54:26,323 ERROR: Exception on /favicon.ico [GET] [in C:\Users\Миша\PycharmProjects\VIT 2.0\venv\lib\site-packages\flask\app.py:1457]
Traceback (most recent call last):
  File "C:\Users\Миша\PycharmProjects\VIT 2.0\venv\lib\site-packages\flask\app.py", line 1516, in full_dispatch_request
    rv = self.dispatch_request()
  File "C:\Users\Миша\PycharmProjects\VIT 2.0\venv\lib\site-packages\flask\app.py", line 1492, in dispatch_request
    self.raise_routing_exception(req)
  File "C:\Users\Миша\PycharmProjects\VIT 2.0\venv\lib\site-packages\flask\app.py", line 1474, in raise_routing_exception
    raise request.routing_exception  # type: ignore
  File "C:\Users\Миша\PycharmProjects\VIT 2.0\venv\lib\site-packages\flask\ctx.py", line 367, in match_request
    result = self.url_adapter.match(return_rule=True)  # type: ignore
  File "C:\Users\Миша\PycharmProjects\VIT 2.0\venv\lib\site-packages\werkzeug\routing.py", line 2041, in match
    raise NotFound()
werkzeug.exceptions.NotFound: 404 Not Found: The requested URL was not found on the server. If you entered the URL manually please check your spelling and try again.

During handling of the above exception, another exception occurred:

Traceback (most recent call last):
  File "C:\Users\Миша\PycharmProjects\VIT 2.0\venv\lib\site-packages\flask\app.py", line 2073, in wsgi_app
    response = self.full_dispatch_request()
  File "C:\Users\Миша\PycharmProjects\VIT 2.0\venv\lib\site-packages\flask\app.py", line 1518, in full_dispatch_request
    rv = self.handle_user_exception(e)
  File "C:\Users\Миша\PycharmProjects\VIT 2.0\venv\lib\site-packages\flask\app.py", line 1386, in handle_user_exception
    return self.handle_http_exception(e)
  File "C:\Users\Миша\PycharmProjects\VIT 2.0\venv\lib\site-packages\flask\app.py", line 1326, in handle_http_exception
    return self.ensure_sync(handler)(e)
  File "C:\Users\Миша\PycharmProjects\VIT 2.0\app\errors.py", line 7, in not_found_error
    return render_template('404.html'), 404
  File "C:\Users\Миша\PycharmProjects\VIT 2.0\venv\lib\site-packages\flask\templating.py", line 147, in render_template
    return _render(
  File "C:\Users\Миша\PycharmProjects\VIT 2.0\venv\lib\site-packages\flask\templating.py", line 128, in _render
    rv = template.render(context)
  File "C:\Users\Миша\PycharmProjects\VIT 2.0\venv\lib\site-packages\jinja2\environment.py", line 1291, in render
    self.environment.handle_exception()
  File "C:\Users\Миша\PycharmProjects\VIT 2.0\venv\lib\site-packages\jinja2\environment.py", line 925, in handle_exception
    raise rewrite_traceback_stack(source=source)
  File "C:\Users\Миша\PycharmProjects\VIT 2.0\app\templates\404.html", line 1, in top-level template code
    {% extends "base.html" %}
  File "C:\Users\Миша\PycharmProjects\VIT 2.0\app\templates\base.html", line 1, in top-level template code
    {% extends 'bootstrap/base.html' %}
  File "C:\Users\Миша\PycharmProjects\VIT 2.0\venv\lib\site-packages\flask_bootstrap\templates\bootstrap\base.html", line 1, in top-level template code
    {% block doc -%}
  File "C:\Users\Миша\PycharmProjects\VIT 2.0\venv\lib\site-packages\flask_bootstrap\templates\bootstrap\base.html", line 4, in block 'doc'
    {%- block html %}
  File "C:\Users\Миша\PycharmProjects\VIT 2.0\venv\lib\site-packages\flask_bootstrap\templates\bootstrap\base.html", line 20, in block 'html'
    {% block body -%}
  File "C:\Users\Миша\PycharmProjects\VIT 2.0\venv\lib\site-packages\flask_bootstrap\templates\bootstrap\base.html", line 26, in block 'body'
    {% block scripts %}
  File "C:\Users\Миша\PycharmProjects\VIT 2.0\app\templates\base.html", line 54, in block 'scripts'
    {{ moment.include() }}
  File "C:\Users\Миша\PycharmProjects\VIT 2.0\venv\lib\site-packages\jinja2\utils.py", line 84, in from_obj
    if hasattr(obj, "jinja_pass_arg"):
jinja2.exceptions.UndefinedError: 'type object' has no attribute 'include'
2021-12-07 13:55:29,021 INFO: Microblog startup [in C:\Users\Миша\PycharmProjects\VIT 2.0\app\__init__.py:49]
2021-12-07 15:29:19,660 INFO: Microblog startup [in C:\Users\Миша\PycharmProjects\VIT 2.0\app\__init__.py:70]
2021-12-07 15:30:00,423 INFO: Microblog startup [in C:\Users\Миша\PycharmProjects\VIT 2.0\app\__init__.py:70]
2021-12-07 15:30:03,699 ERROR: Exception on / [GET] [in C:\Users\Миша\PycharmProjects\VIT 2.0\venv\lib\site-packages\flask\app.py:1457]
Traceback (most recent call last):
  File "C:\Users\Миша\PycharmProjects\VIT 2.0\venv\lib\site-packages\flask\app.py", line 2073, in wsgi_app
    response = self.full_dispatch_request()
  File "C:\Users\Миша\PycharmProjects\VIT 2.0\venv\lib\site-packages\flask\app.py", line 1518, in full_dispatch_request
    rv = self.handle_user_exception(e)
  File "C:\Users\Миша\PycharmProjects\VIT 2.0\venv\lib\site-packages\flask\app.py", line 1516, in full_dispatch_request
    rv = self.dispatch_request()
  File "C:\Users\Миша\PycharmProjects\VIT 2.0\venv\lib\site-packages\flask\app.py", line 1502, in dispatch_request
    return self.ensure_sync(self.view_functions[rule.endpoint])(**req.view_args)
  File "C:\Users\Миша\PycharmProjects\VIT 2.0\venv\lib\site-packages\flask_login\utils.py", line 271, in decorated_view
    return current_app.login_manager.unauthorized()
  File "C:\Users\Миша\PycharmProjects\VIT 2.0\venv\lib\site-packages\flask_login\login_manager.py", line 174, in unauthorized
    redirect_url = make_login_url(login_view, next_url=request.url)
  File "C:\Users\Миша\PycharmProjects\VIT 2.0\venv\lib\site-packages\flask_login\utils.py", line 120, in login_url
    base = expand_login_view(login_view)
  File "C:\Users\Миша\PycharmProjects\VIT 2.0\venv\lib\site-packages\flask_login\utils.py", line 97, in expand_login_view
    return url_for(login_view)
  File "C:\Users\Миша\PycharmProjects\VIT 2.0\venv\lib\site-packages\flask\helpers.py", line 338, in url_for
    return appctx.app.handle_url_build_error(error, endpoint, values)
  File "C:\Users\Миша\PycharmProjects\VIT 2.0\venv\lib\site-packages\flask\helpers.py", line 325, in url_for
    rv = url_adapter.build(
  File "C:\Users\Миша\PycharmProjects\VIT 2.0\venv\lib\site-packages\werkzeug\routing.py", line 2314, in build
    raise BuildError(endpoint, values, method, self)
werkzeug.routing.BuildError: Could not build url for endpoint 'login'. Did you mean 'auth.login' instead?
2021-12-07 15:33:20,465 INFO: Microblog startup [in C:\Users\Миша\PycharmProjects\VIT 2.0\app\__init__.py:70]
2021-12-07 15:33:30,013 ERROR: Exception on / [GET] [in C:\Users\Миша\PycharmProjects\VIT 2.0\venv\lib\site-packages\flask\app.py:1457]
Traceback (most recent call last):
  File "C:\Users\Миша\PycharmProjects\VIT 2.0\venv\lib\site-packages\flask\app.py", line 2073, in wsgi_app
    response = self.full_dispatch_request()
  File "C:\Users\Миша\PycharmProjects\VIT 2.0\venv\lib\site-packages\flask\app.py", line 1518, in full_dispatch_request
    rv = self.handle_user_exception(e)
  File "C:\Users\Миша\PycharmProjects\VIT 2.0\venv\lib\site-packages\flask\app.py", line 1516, in full_dispatch_request
    rv = self.dispatch_request()
  File "C:\Users\Миша\PycharmProjects\VIT 2.0\venv\lib\site-packages\flask\app.py", line 1502, in dispatch_request
    return self.ensure_sync(self.view_functions[rule.endpoint])(**req.view_args)
  File "C:\Users\Миша\PycharmProjects\VIT 2.0\venv\lib\site-packages\flask_login\utils.py", line 271, in decorated_view
    return current_app.login_manager.unauthorized()
  File "C:\Users\Миша\PycharmProjects\VIT 2.0\venv\lib\site-packages\flask_login\login_manager.py", line 174, in unauthorized
    redirect_url = make_login_url(login_view, next_url=request.url)
  File "C:\Users\Миша\PycharmProjects\VIT 2.0\venv\lib\site-packages\flask_login\utils.py", line 120, in login_url
    base = expand_login_view(login_view)
  File "C:\Users\Миша\PycharmProjects\VIT 2.0\venv\lib\site-packages\flask_login\utils.py", line 97, in expand_login_view
    return url_for(login_view)
  File "C:\Users\Миша\PycharmProjects\VIT 2.0\venv\lib\site-packages\flask\helpers.py", line 338, in url_for
    return appctx.app.handle_url_build_error(error, endpoint, values)
  File "C:\Users\Миша\PycharmProjects\VIT 2.0\venv\lib\site-packages\flask\helpers.py", line 325, in url_for
    rv = url_adapter.build(
  File "C:\Users\Миша\PycharmProjects\VIT 2.0\venv\lib\site-packages\werkzeug\routing.py", line 2314, in build
    raise BuildError(endpoint, values, method, self)
werkzeug.routing.BuildError: Could not build url for endpoint 'login'. Did you mean 'auth.login' instead?
2021-12-07 15:35:50,628 INFO: Microblog startup [in C:\Users\Миша\PycharmProjects\VIT 2.0\app\__init__.py:70]
