2021-12-07 16:09:17,155 ERROR: Exception on /index [GET] [in C:\Users\Миша\PycharmProjects\VIT 2.0\venv\lib\site-packages\flask\app.py:1457]
Traceback (most recent call last):
  File "C:\Users\Миша\PycharmProjects\VIT 2.0\venv\lib\site-packages\flask\app.py", line 2073, in wsgi_app
    response = self.full_dispatch_request()
  File "C:\Users\Миша\PycharmProjects\VIT 2.0\venv\lib\site-packages\flask\app.py", line 1518, in full_dispatch_request
    rv = self.handle_user_exception(e)
  File "C:\Users\Миша\PycharmProjects\VIT 2.0\venv\lib\site-packages\flask\app.py", line 1516, in full_dispatch_request
    rv = self.dispatch_request()
  File "C:\Users\Миша\PycharmProjects\VIT 2.0\venv\lib\site-packages\flask\app.py", line 1502, in dispatch_request
    return self.ensure_sync(self.view_functions[rule.endpoint])(**req.view_args)
  File "C:\Users\Миша\PycharmProjects\VIT 2.0\venv\lib\site-packages\flask_login\utils.py", line 272, in decorated_view
    return func(*args, **kwargs)
  File "C:\Users\Миша\PycharmProjects\VIT 2.0\app\main\routes.py", line 22, in index
    posts = current_user.followed_posts().paginate(page, app.config['POSTS_PER_PAGE'], False)  # отображение постов только от отслеживаемых
NameError: name 'app' is not defined
2021-12-07 16:12:52,049 ERROR: Exception on / [GET] [in C:\Users\Миша\PycharmProjects\VIT 2.0\venv\lib\site-packages\flask\app.py:1457]
Traceback (most recent call last):
  File "C:\Users\Миша\PycharmProjects\VIT 2.0\venv\lib\site-packages\flask\app.py", line 2073, in wsgi_app
    response = self.full_dispatch_request()
  File "C:\Users\Миша\PycharmProjects\VIT 2.0\venv\lib\site-packages\flask\app.py", line 1518, in full_dispatch_request
    rv = self.handle_user_exception(e)
  File "C:\Users\Миша\PycharmProjects\VIT 2.0\venv\lib\site-packages\flask\app.py", line 1516, in full_dispatch_request
    rv = self.dispatch_request()
  File "C:\Users\Миша\PycharmProjects\VIT 2.0\venv\lib\site-packages\flask\app.py", line 1502, in dispatch_request
    return self.ensure_sync(self.view_functions[rule.endpoint])(**req.view_args)
  File "C:\Users\Миша\PycharmProjects\VIT 2.0\venv\lib\site-packages\flask_login\utils.py", line 272, in decorated_view
    return func(*args, **kwargs)
  File "C:\Users\Миша\PycharmProjects\VIT 2.0\app\main\routes.py", line 22, in index
    posts = current_user.followed_posts().paginate(page, current_app.config['POSTS_PER_PAGE'], False)  # отображение постов только от отслеживаемых
NameError: name 'app' is not defined
2021-12-07 16:13:50,271 ERROR: Exception on /index [GET] [in C:\Users\Миша\PycharmProjects\VIT 2.0\venv\lib\site-packages\flask\app.py:1457]
Traceback (most recent call last):
  File "C:\Users\Миша\PycharmProjects\VIT 2.0\venv\lib\site-packages\flask\app.py", line 2073, in wsgi_app
    response = self.full_dispatch_request()
  File "C:\Users\Миша\PycharmProjects\VIT 2.0\venv\lib\site-packages\flask\app.py", line 1518, in full_dispatch_request
    rv = self.handle_user_exception(e)
  File "C:\Users\Миша\PycharmProjects\VIT 2.0\venv\lib\site-packages\flask\app.py", line 1516, in full_dispatch_request
    rv = self.dispatch_request()
  File "C:\Users\Миша\PycharmProjects\VIT 2.0\venv\lib\site-packages\flask\app.py", line 1502, in dispatch_request
    return self.ensure_sync(self.view_functions[rule.endpoint])(**req.view_args)
  File "C:\Users\Миша\PycharmProjects\VIT 2.0\venv\lib\site-packages\flask_login\utils.py", line 272, in decorated_view
    return func(*args, **kwargs)
  File "C:\Users\Миша\PycharmProjects\VIT 2.0\app\main\routes.py", line 22, in index
    posts = user.posts.order_by(Post.timestamp.desc()).paginate(
NameError: name 'app' is not defined
2021-12-07 16:14:31,167 ERROR: Exception on /explore [GET] [in C:\Users\Миша\PycharmProjects\VIT 2.0\venv\lib\site-packages\flask\app.py:1457]
Traceback (most recent call last):
  File "C:\Users\Миша\PycharmProjects\VIT 2.0\venv\lib\site-packages\flask\app.py", line 2073, in wsgi_app
    response = self.full_dispatch_request()
  File "C:\Users\Миша\PycharmProjects\VIT 2.0\venv\lib\site-packages\flask\app.py", line 1518, in full_dispatch_request
    rv = self.handle_user_exception(e)
  File "C:\Users\Миша\PycharmProjects\VIT 2.0\venv\lib\site-packages\flask\app.py", line 1516, in full_dispatch_request
    rv = self.dispatch_request()
  File "C:\Users\Миша\PycharmProjects\VIT 2.0\venv\lib\site-packages\flask\app.py", line 1502, in dispatch_request
    return self.ensure_sync(self.view_functions[rule.endpoint])(**req.view_args)
  File "C:\Users\Миша\PycharmProjects\VIT 2.0\venv\lib\site-packages\flask_login\utils.py", line 272, in decorated_view
    return func(*args, **kwargs)
  File "C:\Users\Миша\PycharmProjects\VIT 2.0\app\main\routes.py", line 103, in explore
    def explore():  # логика страницы с постами от всех пользователей
NameError: name 'app' is not defined
2021-12-07 16:16:27,839 ERROR: Exception on / [GET] [in C:\Users\Миша\PycharmProjects\VIT 2.0\venv\lib\site-packages\flask\app.py:1457]
Traceback (most recent call last):
  File "C:\Users\Миша\PycharmProjects\VIT 2.0\venv\lib\site-packages\flask\app.py", line 2073, in wsgi_app
    response = self.full_dispatch_request()
  File "C:\Users\Миша\PycharmProjects\VIT 2.0\venv\lib\site-packages\flask\app.py", line 1518, in full_dispatch_request
    rv = self.handle_user_exception(e)
  File "C:\Users\Миша\PycharmProjects\VIT 2.0\venv\lib\site-packages\flask\app.py", line 1516, in full_dispatch_request
    rv = self.dispatch_request()
  File "C:\Users\Миша\PycharmProjects\VIT 2.0\venv\lib\site-packages\flask\app.py", line 1502, in dispatch_request
    return self.ensure_sync(self.view_functions[rule.endpoint])(**req.view_args)
  File "C:\Users\Миша\PycharmProjects\VIT 2.0\venv\lib\site-packages\flask_login\utils.py", line 272, in decorated_view
    return func(*args, **kwargs)
  File "C:\Users\Миша\PycharmProjects\VIT 2.0\app\main\routes.py", line 22, in index
    posts = current_user.followed_posts().paginate(
NameError: name 'app' is not defined
2021-12-07 16:18:09,532 INFO: Microblog startup [in C:\Users\Миша\PycharmProjects\VIT 2.0\app\__init__.py:70]
2021-12-07 16:18:28,123 ERROR: Exception on /index [GET] [in C:\Users\Миша\PycharmProjects\VIT 2.0\venv\lib\site-packages\flask\app.py:1457]
Traceback (most recent call last):
  File "C:\Users\Миша\PycharmProjects\VIT 2.0\venv\lib\site-packages\flask\app.py", line 2073, in wsgi_app
    response = self.full_dispatch_request()
  File "C:\Users\Миша\PycharmProjects\VIT 2.0\venv\lib\site-packages\flask\app.py", line 1518, in full_dispatch_request
    rv = self.handle_user_exception(e)
  File "C:\Users\Миша\PycharmProjects\VIT 2.0\venv\lib\site-packages\flask\app.py", line 1516, in full_dispatch_request
    rv = self.dispatch_request()
  File "C:\Users\Миша\PycharmProjects\VIT 2.0\venv\lib\site-packages\flask\app.py", line 1502, in dispatch_request
    return self.ensure_sync(self.view_functions[rule.endpoint])(**req.view_args)
  File "C:\Users\Миша\PycharmProjects\VIT 2.0\venv\lib\site-packages\flask_login\utils.py", line 271, in decorated_view
    return current_app.login_manager.unauthorized()
  File "C:\Users\Миша\PycharmProjects\VIT 2.0\venv\lib\site-packages\flask_login\login_manager.py", line 174, in unauthorized
    redirect_url = make_login_url(login_view, next_url=request.url)
  File "C:\Users\Миша\PycharmProjects\VIT 2.0\venv\lib\site-packages\flask_login\utils.py", line 120, in login_url
    base = expand_login_view(login_view)
  File "C:\Users\Миша\PycharmProjects\VIT 2.0\venv\lib\site-packages\flask_login\utils.py", line 97, in expand_login_view
    return url_for(login_view)
  File "C:\Users\Миша\PycharmProjects\VIT 2.0\venv\lib\site-packages\flask\helpers.py", line 338, in url_for
    return appctx.app.handle_url_build_error(error, endpoint, values)
  File "C:\Users\Миша\PycharmProjects\VIT 2.0\venv\lib\site-packages\flask\helpers.py", line 325, in url_for
    rv = url_adapter.build(
  File "C:\Users\Миша\PycharmProjects\VIT 2.0\venv\lib\site-packages\werkzeug\routing.py", line 2314, in build
    raise BuildError(endpoint, values, method, self)
werkzeug.routing.BuildError: Could not build url for endpoint 'login'. Did you mean 'auth.login' instead?
