2021-12-07 16:41:06,516 ERROR: Exception on / [GET] [in C:\Users\Миша\PycharmProjects\VIT 2.0\venv\lib\site-packages\flask\app.py:1457]
Traceback (most recent call last):
  File "C:\Users\Миша\PycharmProjects\VIT 2.0\venv\lib\site-packages\flask\app.py", line 2073, in wsgi_app
    response = self.full_dispatch_request()
  File "C:\Users\Миша\PycharmProjects\VIT 2.0\venv\lib\site-packages\flask\app.py", line 1518, in full_dispatch_request
    rv = self.handle_user_exception(e)
  File "C:\Users\Миша\PycharmProjects\VIT 2.0\venv\lib\site-packages\flask\app.py", line 1516, in full_dispatch_request
    rv = self.dispatch_request()
  File "C:\Users\Миша\PycharmProjects\VIT 2.0\venv\lib\site-packages\flask\app.py", line 1502, in dispatch_request
    return self.ensure_sync(self.view_functions[rule.endpoint])(**req.view_args)
  File "C:\Users\Миша\PycharmProjects\VIT 2.0\venv\lib\site-packages\flask_login\utils.py", line 271, in decorated_view
    return current_app.login_manager.unauthorized()
  File "C:\Users\Миша\PycharmProjects\VIT 2.0\venv\lib\site-packages\flask_login\login_manager.py", line 174, in unauthorized
    redirect_url = make_login_url(login_view, next_url=request.url)
  File "C:\Users\Миша\PycharmProjects\VIT 2.0\venv\lib\site-packages\flask_login\utils.py", line 120, in login_url
    base = expand_login_view(login_view)
  File "C:\Users\Миша\PycharmProjects\VIT 2.0\venv\lib\site-packages\flask_login\utils.py", line 97, in expand_login_view
    return url_for(login_view)
  File "C:\Users\Миша\PycharmProjects\VIT 2.0\venv\lib\site-packages\flask\helpers.py", line 338, in url_for
    return appctx.app.handle_url_build_error(error, endpoint, values)
  File "C:\Users\Миша\PycharmProjects\VIT 2.0\venv\lib\site-packages\flask\helpers.py", line 325, in url_for
    rv = url_adapter.build(
  File "C:\Users\Миша\PycharmProjects\VIT 2.0\venv\lib\site-packages\werkzeug\routing.py", line 2314, in build
    raise BuildError(endpoint, values, method, self)
werkzeug.routing.BuildError: Could not build url for endpoint 'login'. Did you mean 'auth.login' instead?
2021-12-07 16:42:47,429 INFO: Microblog startup [in C:\Users\Миша\PycharmProjects\VIT 2.0\app\__init__.py:70]
2021-12-07 16:43:27,549 INFO: Microblog startup [in C:\Users\Миша\PycharmProjects\VIT 2.0\app\__init__.py:70]
2021-12-07 16:45:19,090 INFO: Microblog startup [in C:\Users\Миша\PycharmProjects\VIT 2.0\app\__init__.py:70]
2021-12-07 16:47:34,844 INFO: Microblog startup [in C:\Users\Миша\PycharmProjects\VIT 2.0\app\__init__.py:70]
2021-12-07 16:47:54,292 INFO: Microblog startup [in C:\Users\Миша\PycharmProjects\VIT 2.0\app\__init__.py:70]
2021-12-07 16:49:21,999 INFO: Microblog startup [in C:\Users\Миша\PycharmProjects\VIT 2.0\app\__init__.py:70]
2021-12-07 16:49:28,300 ERROR: Exception on /index [GET] [in C:\Program Files\Python38\lib\site-packages\flask\app.py:1454]
Traceback (most recent call last):
  File "C:\Program Files\Python38\lib\site-packages\flask\app.py", line 2070, in wsgi_app
    response = self.full_dispatch_request()
  File "C:\Program Files\Python38\lib\site-packages\flask\app.py", line 1515, in full_dispatch_request
    rv = self.handle_user_exception(e)
  File "C:\Program Files\Python38\lib\site-packages\flask\app.py", line 1513, in full_dispatch_request
    rv = self.dispatch_request()
  File "C:\Program Files\Python38\lib\site-packages\flask\app.py", line 1499, in dispatch_request
    return self.ensure_sync(self.view_functions[rule.endpoint])(**req.view_args)
  File "C:\Program Files\Python38\lib\site-packages\flask_login\utils.py", line 271, in decorated_view
    return current_app.login_manager.unauthorized()
  File "C:\Program Files\Python38\lib\site-packages\flask_login\login_manager.py", line 174, in unauthorized
    redirect_url = make_login_url(login_view, next_url=request.url)
  File "C:\Program Files\Python38\lib\site-packages\flask_login\utils.py", line 120, in login_url
    base = expand_login_view(login_view)
  File "C:\Program Files\Python38\lib\site-packages\flask_login\utils.py", line 97, in expand_login_view
    return url_for(login_view)
  File "C:\Program Files\Python38\lib\site-packages\flask\helpers.py", line 338, in url_for
    return appctx.app.handle_url_build_error(error, endpoint, values)
  File "C:\Program Files\Python38\lib\site-packages\flask\helpers.py", line 325, in url_for
    rv = url_adapter.build(
  File "C:\Program Files\Python38\lib\site-packages\werkzeug\routing.py", line 2305, in build
    raise BuildError(endpoint, values, method, self)
werkzeug.routing.BuildError: Could not build url for endpoint 'login'. Did you mean 'auth.login' instead?
2021-12-07 16:49:52,653 ERROR: Exception on /index [GET] [in C:\Program Files\Python38\lib\site-packages\flask\app.py:1454]
Traceback (most recent call last):
  File "C:\Program Files\Python38\lib\site-packages\flask\app.py", line 2070, in wsgi_app
    response = self.full_dispatch_request()
  File "C:\Program Files\Python38\lib\site-packages\flask\app.py", line 1515, in full_dispatch_request
    rv = self.handle_user_exception(e)
  File "C:\Program Files\Python38\lib\site-packages\flask\app.py", line 1513, in full_dispatch_request
    rv = self.dispatch_request()
  File "C:\Program Files\Python38\lib\site-packages\flask\app.py", line 1499, in dispatch_request
    return self.ensure_sync(self.view_functions[rule.endpoint])(**req.view_args)
  File "C:\Program Files\Python38\lib\site-packages\flask_login\utils.py", line 271, in decorated_view
    return current_app.login_manager.unauthorized()
  File "C:\Program Files\Python38\lib\site-packages\flask_login\login_manager.py", line 174, in unauthorized
    redirect_url = make_login_url(login_view, next_url=request.url)
  File "C:\Program Files\Python38\lib\site-packages\flask_login\utils.py", line 120, in login_url
    base = expand_login_view(login_view)
  File "C:\Program Files\Python38\lib\site-packages\flask_login\utils.py", line 97, in expand_login_view
    return url_for(login_view)
  File "C:\Program Files\Python38\lib\site-packages\flask\helpers.py", line 338, in url_for
    return appctx.app.handle_url_build_error(error, endpoint, values)
  File "C:\Program Files\Python38\lib\site-packages\flask\helpers.py", line 325, in url_for
    rv = url_adapter.build(
  File "C:\Program Files\Python38\lib\site-packages\werkzeug\routing.py", line 2305, in build
    raise BuildError(endpoint, values, method, self)
werkzeug.routing.BuildError: Could not build url for endpoint 'login'. Did you mean 'auth.login' instead?
2021-12-07 16:50:48,889 INFO: Microblog startup [in C:\Users\Миша\PycharmProjects\VIT 2.0\app\__init__.py:70]
